<?xml version="1.0" encoding="utf-8"?>

<robot name="wallclimbingrobot">
  <link name="world"/>
  <joint name="world_to_base" type="fixed">
    <parent link="world"/>
    <child link="base_link"/>
    <origin xyz="0 0 0" rpy="0 0 0"/>
  </joint>

  <link name="base_link">
    <inertial>
      <origin xyz="0 0 -0.00139167053492445" rpy="0 0 0" />
      <mass value="2.24200509812134" />
      <inertia ixx="0.0249086640869241" ixy="4.01026389598321E-18" ixz="-5.31210156988019E-18"
               iyy="0.0777395584720522" iyz="6.75854069904095E-19" izz="0.100518609386422" />
    </inertial>
    <visual>
      <origin xyz="0 0 0" rpy="0 0 0" />
      <geometry>
        <mesh filename="/home/pretom/ros2_ws/src/wallclimbingrobot/meshes/base_link.STL" />
      </geometry>
      <material name="red">
        <color rgba="1.0 0.0 0.0 1" />
      </material>
    </visual>
    <collision>
      <origin xyz="0 0 0" rpy="0 0 0" />
      <geometry>
        <mesh filename="/home/pretom/ros2_ws/src/wallclimbingrobot/meshes/base_link.STL" />
      </geometry>
    </collision>
  </link>

  <link name="link_BR">
    <inertial>
      <origin xyz="-2.7756E-16 0.023324 1.3878E-16" rpy="0 0 0" />
      <mass value="0.39375" />
      <inertia ixx="0.00035222" ixy="7.5731E-21" ixz="-6.1531E-21"
               iyy="0.00058248" iyz="1.8933E-21" izz="0.00035222" />
    </inertial>
    <visual>
      <origin xyz="0 0 0" rpy="0 0 0" />
      <geometry>
        <mesh filename="/home/pretom/ros2_ws/src/wallclimbingrobot/meshes/link_BR.STL" />
      </geometry>
      <material name="black">
        <color rgba="0.1 0.1 0.1 1" />
      </material>
    </visual>
    <collision>
      <origin xyz="0 0 0" rpy="0 0 0" />
      <geometry>
        <mesh filename="/home/pretom/ros2_ws/src/wallclimbingrobot/meshes/link_BR.STL" />
      </geometry>
    </collision>
  </link>
  <joint name="joint_BR" type="continuous">
    <origin xyz="-0.26814 -0.2 -0.04" rpy="0 0 0" />
    <parent link="base_link" />
    <child link="link_BR" />
    <axis xyz="0 1 0" />
  </joint>

  <link name="link_BL">
    <inertial>
      <origin xyz="-5.5511E-17 -0.023324 5.5511E-17" rpy="0 0 0" />
      <mass value="0.39375" />
      <inertia ixx="0.00035222" ixy="5.4144E-21" ixz="0"
               iyy="0.00058248" iyz="-1.2032E-19" izz="0.00035222" />
    </inertial>
    <visual>
      <origin xyz="0 0 0" rpy="0 0 0" />
      <geometry>
        <mesh filename="/home/pretom/ros2_ws/src/wallclimbingrobot/meshes/link_BL.STL" />
      </geometry>
      <material name="black">
        <color rgba="0.1 0.1 0.1 1" />
      </material>
    </visual>
    <collision>
      <origin xyz="0 0 0" rpy="0 0 0" />
      <geometry>
        <mesh filename="/home/pretom/ros2_ws/src/wallclimbingrobot/meshes/link_BL.STL" />
      </geometry>
    </collision>
  </link>
  <joint name="joint_BL" type="continuous">
    <origin xyz="-0.26814 0.2 -0.04" rpy="0 0.32175 0" />
    <parent link="base_link" />
    <child link="link_BL" />
    <axis xyz="0 1 0" />
  </joint>

  <link name="link_FL">
    <inertial>
      <origin xyz="1.3878E-17 -0.023324 0" rpy="0 0 0" />
      <mass value="0.39375" />
      <inertia ixx="0.00035222" ixy="2.6341E-21" ixz="-2.2739E-21"
               iyy="0.00058248" iyz="-2.1973E-19" izz="0.00035222" />
    </inertial>
    <visual>
      <origin xyz="0 0 0" rpy="0 0 0" />
      <geometry>
        <mesh filename="/home/pretom/ros2_ws/src/wallclimbingrobot/meshes/link_FL.STL" />
      </geometry>
      <material name="black">
        <color rgba="0.1 0.1 0.1 1" />
      </material>
    </visual>
    <collision>
      <origin xyz="0 0 0" rpy="0 0 0" />
      <geometry>
        <mesh filename="/home/pretom/ros2_ws/src/wallclimbingrobot/meshes/link_FL.STL" />
      </geometry>
    </collision>
  </link>
  <joint name="joint_FL" type="continuous">
    <origin xyz="0.26814 0.2 -0.04" rpy="0 0 0" />
    <parent link="base_link" />
    <child link="link_FL" />
    <axis xyz="0 1 0" />
  </joint>

  <link name="link_FR">
    <inertial>
      <origin xyz="1.3878E-17 0.023324 0" rpy="0 0 0" />
      <mass value="0.39375" />
      <inertia ixx="0.00035222" ixy="-9.2853E-22" ixz="-4.4492E-21"
               iyy="0.00058248" iyz="6.9654E-21" izz="0.00035222" />
    </inertial>
    <visual>
      <origin xyz="0 0 0" rpy="0 0 0" />
      <geometry>
        <mesh filename="/home/pretom/ros2_ws/src/wallclimbingrobot/meshes/link_FR.STL" />
      </geometry>
      <material name="black">
        <color rgba="0.1 0.1 0.1 1" />
      </material>
    </visual>
    <collision>
      <origin xyz="0 0 0" rpy="0 0 0" />
      <geometry>
        <mesh filename="/home/pretom/ros2_ws/src/wallclimbingrobot/meshes/link_FR.STL" />
      </geometry>
    </collision>
  </link>
  <joint name="joint_FR" type="continuous">
    <origin xyz="0.26814 -0.2 -0.04" rpy="0 0 0" />
    <parent link="base_link" />
    <child link="link_FR" />
    <axis xyz="0 1 0" />
  </joint>
  <!-- Gazebo differential drive plugin -->
  <gazebo>
    <plugin filename="gz-sim-diff-drive-system"
            name="gz::sim::systems::DiffDrive">
      <left_joint>joint_FL</left_joint>
      <left_joint>joint_BL</left_joint>
      <right_joint>joint_FR</right_joint>
      <right_joint>joint_BR</right_joint>
      <wheel_separation>0.4</wheel_separation>
      <wheel_radius>0.05</wheel_radius>
      <odom_publish_frequency>10</odom_publish_frequency>
      <topic>cmd_vel</topic>
      <odom_topic>odom</odom_topic>
      <frame_id>odom</frame_id>
      <child_frame_id>base_link</child_frame_id>
    </plugin>
  </gazebo>

  <!-- Joint state publisher plugin -->
  <gazebo>
    <plugin filename="gz-sim-joint-state-publisher-system"
            name="gz::sim::systems::JointStatePublisher">
    </plugin>
  </gazebo>
</robot>
